<?xml version="1.0" ?>
<!-- =================================================================================== -->
<!-- |    This document was autogenerated by xacro from snake_robot_description/urdf/snake_urdf.xacro | -->
<!-- |    EDITING THIS FILE BY HAND IS NOT RECOMMENDED                                 | -->
<!-- =================================================================================== -->
<robot name="snake robot">
  <!-- Define a color materials with RGBA color values -->
  <material name="blue">
    <color rgba="0 0 0.8 0.5"/>
  </material>
  <material name="white">
    <color rgba="1 1 1 0.5"/>
  </material>
  <material name="red">
    <color rgba="0.8 0 0 0.5"/>
  </material>
  <link name="base_link">
    <visual>
      <geometry>
        <cylinder length="0.4" radius="0.1"/>
      </geometry>
      <origin rpy="0 1.5707963267948966 1.5707963267948966" xyz="0 0 0.1"/>
      <material name="red"/>
    </visual>
    <!-- Collision properties of the link -->
    <collision>
      <geometry>
        <cylinder length="0.4" radius="0.1"/>
      </geometry>
      <origin rpy="0 1.5707963267948966 1.5707963267948966" xyz="0 0 0.1"/>
    </collision>
    <inertial>
      <origin rpy="0 1.5707963267948966 1.5707963267948966" xyz="0 0 0.1"/>
      <mass value="1"/>
      <!-- Calculate and set the inertia tensor values, formula source https://en.wikipedia.org/wiki/List_of_moments_of_inertia -->
      <inertia ixx="0.015833333333333335" ixy="0" ixz="0" iyy="0.015833333333333335" iyz="0" izz="0.005000000000000001"/>
    </inertial>
  </link>
  <joint name="base_to_link1_Zaxis" type="revolute">
    <axis xyz="0 0 1"/>
    <limit effort="1000.0" lower="-1.5707963267948966" upper="1.5707963267948966" velocity="0.5"/>
    <parent link="base_link"/>
    <child link="link1"/>
    <origin xyz="0 0.2 0.1"/>
    <dynamics damping="0.1" friction="0.05"/>
  </joint>
  <link name="link1">
    <visual>
      <geometry>
        <cylinder length="0.4" radius="0.1"/>
      </geometry>
      <origin rpy="0 1.5707963267948966 1.5707963267948966" xyz="0 0.2 0"/>
      <material name="blue"/>
    </visual>
    <!-- Collision properties of the link -->
    <collision>
      <geometry>
        <cylinder length="0.4" radius="0.1"/>
      </geometry>
      <origin rpy="0 1.5707963267948966 1.5707963267948966" xyz="0 0.2 0"/>
    </collision>
    <inertial>
      <origin rpy="0 1.5707963267948966 1.5707963267948966" xyz="0 0.2 0"/>
      <mass value="1"/>
      <!-- Calculate and set the inertia tensor values, formula source https://en.wikipedia.org/wiki/List_of_moments_of_inertia -->
      <inertia ixx="0.015833333333333335" ixy="0" ixz="0" iyy="0.015833333333333335" iyz="0" izz="0.005000000000000001"/>
    </inertial>
  </link>
  <joint name="link1_to_link2_Xaxis" type="revolute">
    <axis xyz="1 0 0"/>
    <limit effort="1000.0" lower="-1.5707963267948966" upper="1.5707963267948966" velocity="0.5"/>
    <parent link="link1"/>
    <child link="link2"/>
    <origin xyz="0 0.4 0"/>
    <!--this needs to be investigated, it is adding friction etc-->
    <dynamics damping="0.1" friction="0.05"/>
  </joint>
  <link name="link2">
    <visual>
      <geometry>
        <cylinder length="0.4" radius="0.1"/>
      </geometry>
      <origin rpy="0 1.5707963267948966 1.5707963267948966" xyz="0 0.2 0"/>
      <material name="red"/>
    </visual>
    <!-- Collision properties of the link -->
    <collision>
      <geometry>
        <cylinder length="0.4" radius="0.1"/>
      </geometry>
      <origin rpy="0 1.5707963267948966 1.5707963267948966" xyz="0 0.2 0"/>
    </collision>
    <inertial>
      <origin rpy="0 1.5707963267948966 1.5707963267948966" xyz="0 0.2 0"/>
      <mass value="1"/>
      <!-- Calculate and set the inertia tensor values, formula source https://en.wikipedia.org/wiki/List_of_moments_of_inertia -->
      <inertia ixx="0.015833333333333335" ixy="0" ixz="0" iyy="0.015833333333333335" iyz="0" izz="0.005000000000000001"/>
    </inertial>
  </link>
  <joint name="link2_to_link3_Zaxis" type="revolute">
    <axis xyz="0 0 1"/>
    <limit effort="1000.0" lower="-1.5707963267948966" upper="1.5707963267948966" velocity="0.5"/>
    <parent link="link2"/>
    <child link="link3"/>
    <origin xyz="0 0.4 0"/>
    <dynamics damping="0.1" friction="0.05"/>
  </joint>
  <link name="link3">
    <visual>
      <geometry>
        <cylinder length="0.4" radius="0.1"/>
      </geometry>
      <origin rpy="0 1.5707963267948966 1.5707963267948966" xyz="0 0.2 0"/>
      <material name="blue"/>
    </visual>
    <!-- Collision properties of the link -->
    <collision>
      <geometry>
        <cylinder length="0.4" radius="0.1"/>
      </geometry>
      <origin rpy="0 1.5707963267948966 1.5707963267948966" xyz="0 0.2 0"/>
    </collision>
    <inertial>
      <origin rpy="0 1.5707963267948966 1.5707963267948966" xyz="0 0.2 0"/>
      <mass value="1"/>
      <!-- Calculate and set the inertia tensor values, formula source https://en.wikipedia.org/wiki/List_of_moments_of_inertia -->
      <inertia ixx="0.015833333333333335" ixy="0" ixz="0" iyy="0.015833333333333335" iyz="0" izz="0.005000000000000001"/>
    </inertial>
  </link>
  <joint name="link3_to_link4_Xaxis" type="revolute">
    <axis xyz="1 0 0"/>
    <limit effort="1000.0" lower="-1.5707963267948966" upper="1.5707963267948966" velocity="0.5"/>
    <parent link="link3"/>
    <child link="link4"/>
    <origin xyz="0 0.4 0"/>
    <!--this needs to be investigated, it is adding friction etc-->
    <dynamics damping="0.1" friction="0.05"/>
  </joint>
  <link name="link4">
    <visual>
      <geometry>
        <cylinder length="0.4" radius="0.1"/>
      </geometry>
      <origin rpy="0 1.5707963267948966 1.5707963267948966" xyz="0 0.2 0"/>
      <material name="red"/>
    </visual>
    <!-- Collision properties of the link -->
    <collision>
      <geometry>
        <cylinder length="0.4" radius="0.1"/>
      </geometry>
      <origin rpy="0 1.5707963267948966 1.5707963267948966" xyz="0 0.2 0"/>
    </collision>
    <inertial>
      <origin rpy="0 1.5707963267948966 1.5707963267948966" xyz="0 0.2 0"/>
      <mass value="1"/>
      <!-- Calculate and set the inertia tensor values, formula source https://en.wikipedia.org/wiki/List_of_moments_of_inertia -->
      <inertia ixx="0.015833333333333335" ixy="0" ixz="0" iyy="0.015833333333333335" iyz="0" izz="0.005000000000000001"/>
    </inertial>
  </link>
  <joint name="link4_to_link5_Zaxis" type="revolute">
    <axis xyz="0 0 1"/>
    <limit effort="1000.0" lower="-1.5707963267948966" upper="1.5707963267948966" velocity="0.5"/>
    <parent link="link4"/>
    <child link="link5"/>
    <origin xyz="0 0.4 0"/>
    <dynamics damping="0.1" friction="0.05"/>
  </joint>
  <link name="link5">
    <visual>
      <geometry>
        <cylinder length="0.4" radius="0.1"/>
      </geometry>
      <origin rpy="0 1.5707963267948966 1.5707963267948966" xyz="0 0.2 0"/>
      <material name="blue"/>
    </visual>
    <!-- Collision properties of the link -->
    <collision>
      <geometry>
        <cylinder length="0.4" radius="0.1"/>
      </geometry>
      <origin rpy="0 1.5707963267948966 1.5707963267948966" xyz="0 0.2 0"/>
    </collision>
    <inertial>
      <origin rpy="0 1.5707963267948966 1.5707963267948966" xyz="0 0.2 0"/>
      <mass value="1"/>
      <!-- Calculate and set the inertia tensor values, formula source https://en.wikipedia.org/wiki/List_of_moments_of_inertia -->
      <inertia ixx="0.015833333333333335" ixy="0" ixz="0" iyy="0.015833333333333335" iyz="0" izz="0.005000000000000001"/>
    </inertial>
  </link>
  <joint name="link5_to_link6_Xaxis" type="revolute">
    <axis xyz="1 0 0"/>
    <limit effort="1000.0" lower="-1.5707963267948966" upper="1.5707963267948966" velocity="0.5"/>
    <parent link="link5"/>
    <child link="link6"/>
    <origin xyz="0 0.4 0"/>
    <!--this needs to be investigated, it is adding friction etc-->
    <dynamics damping="0.1" friction="0.05"/>
  </joint>
  <link name="link6">
    <visual>
      <geometry>
        <cylinder length="0.4" radius="0.1"/>
      </geometry>
      <origin rpy="0 1.5707963267948966 1.5707963267948966" xyz="0 0.2 0"/>
      <material name="red"/>
    </visual>
    <!-- Collision properties of the link -->
    <collision>
      <geometry>
        <cylinder length="0.4" radius="0.1"/>
      </geometry>
      <origin rpy="0 1.5707963267948966 1.5707963267948966" xyz="0 0.2 0"/>
    </collision>
    <inertial>
      <origin rpy="0 1.5707963267948966 1.5707963267948966" xyz="0 0.2 0"/>
      <mass value="1"/>
      <!-- Calculate and set the inertia tensor values, formula source https://en.wikipedia.org/wiki/List_of_moments_of_inertia -->
      <inertia ixx="0.015833333333333335" ixy="0" ixz="0" iyy="0.015833333333333335" iyz="0" izz="0.005000000000000001"/>
    </inertial>
  </link>
  <joint name="link6_to_link7_Zaxis" type="revolute">
    <axis xyz="0 0 1"/>
    <limit effort="1000.0" lower="-1.5707963267948966" upper="1.5707963267948966" velocity="0.5"/>
    <parent link="link6"/>
    <child link="link7"/>
    <origin xyz="0 0.4 0"/>
    <dynamics damping="0.1" friction="0.05"/>
  </joint>
  <link name="link7">
    <visual>
      <geometry>
        <cylinder length="0.4" radius="0.1"/>
      </geometry>
      <origin rpy="0 1.5707963267948966 1.5707963267948966" xyz="0 0.2 0"/>
      <material name="blue"/>
    </visual>
    <!-- Collision properties of the link -->
    <collision>
      <geometry>
        <cylinder length="0.4" radius="0.1"/>
      </geometry>
      <origin rpy="0 1.5707963267948966 1.5707963267948966" xyz="0 0.2 0"/>
    </collision>
    <inertial>
      <origin rpy="0 1.5707963267948966 1.5707963267948966" xyz="0 0.2 0"/>
      <mass value="1"/>
      <!-- Calculate and set the inertia tensor values, formula source https://en.wikipedia.org/wiki/List_of_moments_of_inertia -->
      <inertia ixx="0.015833333333333335" ixy="0" ixz="0" iyy="0.015833333333333335" iyz="0" izz="0.005000000000000001"/>
    </inertial>
  </link>
  <joint name="link7_to_link8_Xaxis" type="revolute">
    <axis xyz="1 0 0"/>
    <limit effort="1000.0" lower="-1.5707963267948966" upper="1.5707963267948966" velocity="0.5"/>
    <parent link="link7"/>
    <child link="link8"/>
    <origin xyz="0 0.4 0"/>
    <!--this needs to be investigated, it is adding friction etc-->
    <dynamics damping="0.1" friction="0.05"/>
  </joint>
  <link name="link8">
    <visual>
      <geometry>
        <cylinder length="0.4" radius="0.1"/>
      </geometry>
      <origin rpy="0 1.5707963267948966 1.5707963267948966" xyz="0 0.2 0"/>
      <material name="red"/>
    </visual>
    <!-- Collision properties of the link -->
    <collision>
      <geometry>
        <cylinder length="0.4" radius="0.1"/>
      </geometry>
      <origin rpy="0 1.5707963267948966 1.5707963267948966" xyz="0 0.2 0"/>
    </collision>
    <inertial>
      <origin rpy="0 1.5707963267948966 1.5707963267948966" xyz="0 0.2 0"/>
      <mass value="1"/>
      <!-- Calculate and set the inertia tensor values, formula source https://en.wikipedia.org/wiki/List_of_moments_of_inertia -->
      <inertia ixx="0.015833333333333335" ixy="0" ixz="0" iyy="0.015833333333333335" iyz="0" izz="0.005000000000000001"/>
    </inertial>
  </link>
  <gazebo reference="base_link">
    <material>Gazebo/Red</material>
    <mu1>0.01</mu1>
    <mu2>0.05</mu2>
  </gazebo>
  <gazebo reference="link1">
    <material>Gazebo/Blue</material>
    <mu1>0.01</mu1>
    <mu2>0.05</mu2>
  </gazebo>
  <gazebo reference="link2">
    <material>Gazebo/Red</material>
    <mu1>0.01</mu1>
    <mu2>0.05</mu2>
  </gazebo>
  <gazebo reference="link3">
    <material>Gazebo/Blue</material>
    <mu1>0.01</mu1>
    <mu2>0.05</mu2>
  </gazebo>
  <gazebo reference="link4">
    <material>Gazebo/Red</material>
    <mu1>0.01</mu1>
    <mu2>0.05</mu2>
  </gazebo>
  <gazebo reference="link5">
    <material>Gazebo/Blue</material>
    <mu1>0.01</mu1>
    <mu2>0.05</mu2>
  </gazebo>
  <gazebo reference="link6">
    <material>Gazebo/Red</material>
    <mu1>0.01</mu1>
    <mu2>0.05</mu2>
  </gazebo>
  <gazebo reference="link7">
    <material>Gazebo/Blue</material>
    <mu1>0.01</mu1>
    <mu2>0.05</mu2>
  </gazebo>
  <gazebo reference="link8">
    <material>Gazebo/Red</material>
    <mu1>0.01</mu1>
    <mu2>0.05</mu2>
  </gazebo>
  <ros2_control name="GazeboSystem" type="system">
    <hardware>
      <plugin>gazebo_ros2_control/GazeboSystem</plugin>
    </hardware>
    <joint name="base_to_link1_Zaxis">
      <command_interface name="effort">
        <param name="min">-200</param>
        <param name="max">200</param>
      </command_interface>
      <state_interface name="effort"/>
      <state_interface name="position"/>
      <state_interface name="velocity"/>
    </joint>
    <joint name="link1_to_link2_Xaxis">
      <command_interface name="effort">
        <param name="min">-200</param>
        <param name="max">200</param>
      </command_interface>
      <state_interface name="effort"/>
      <state_interface name="position"/>
      <state_interface name="velocity"/>
    </joint>
    <joint name="link2_to_link3_Zaxis">
      <command_interface name="effort">
        <param name="min">-200</param>
        <param name="max">200</param>
      </command_interface>
      <state_interface name="effort"/>
      <state_interface name="position"/>
      <state_interface name="velocity"/>
    </joint>
    <joint name="link3_to_link4_Xaxis">
      <command_interface name="effort">
        <param name="min">-200</param>
        <param name="max">200</param>
      </command_interface>
      <state_interface name="effort"/>
      <state_interface name="position"/>
      <state_interface name="velocity"/>
    </joint>
    <joint name="link4_to_link5_Zaxis">
      <command_interface name="effort">
        <param name="min">-200</param>
        <param name="max">200</param>
      </command_interface>
      <state_interface name="effort"/>
      <state_interface name="position"/>
      <state_interface name="velocity"/>
    </joint>
    <joint name="link5_to_link6_Xaxis">
      <command_interface name="effort">
        <param name="min">-200</param>
        <param name="max">200</param>
      </command_interface>
      <state_interface name="effort"/>
      <state_interface name="position"/>
      <state_interface name="velocity"/>
    </joint>
    <joint name="link6_to_link7_Zaxis">
      <command_interface name="effort">
        <param name="min">-200</param>
        <param name="max">200</param>
      </command_interface>
      <state_interface name="effort"/>
      <state_interface name="position"/>
      <state_interface name="velocity"/>
    </joint>
    <joint name="link7_to_link8_Xaxis">
      <command_interface name="effort">
        <param name="min">-200</param>
        <param name="max">200</param>
      </command_interface>
      <state_interface name="effort"/>
      <state_interface name="position"/>
      <state_interface name="velocity"/>
    </joint>
  </ros2_control>
  <gazebo>
    <plugin filename="libgazebo_ros2_control.so" name="gazebo_ros2_control">
      <robot_sim_type>gazebo_ros2_control/GazeboSystem</robot_sim_type>
      <parameters>/home/mohit/GITHUBRepos/ROS_Gazibo_learning/snake_ws/src/install/snake_robot_description/share/snake_robot_description/config/my_controllers.yaml</parameters>
    </plugin>
  </gazebo>
  <transmission name="base_to_link1_tran">
    <type>transmission_interface/SimpleTransmission</type>
    <actuator name="base_to_link1_motor">
      <mechanicalReduction>1</mechanicalReduction>
    </actuator>
    <joint name="base_to_link1_Zaxis">
      <hardwareInterface>hardware_interface/EffortJointInterface</hardwareInterface>
    </joint>
  </transmission>
  <transmission name="link1_to_link2_tran">
    <type>transmission_interface/SimpleTransmission</type>
    <actuator name="link1_to_link2_motor">
      <mechanicalReduction>1</mechanicalReduction>
    </actuator>
    <joint name="link1_to_link2_Xaxis">
      <hardwareInterface>hardware_interface/EffortJointInterface</hardwareInterface>
    </joint>
  </transmission>
  <transmission name="link2_to_link3_tran">
    <type>transmission_interface/SimpleTransmission</type>
    <actuator name="link2_to_link3_motor">
      <mechanicalReduction>1</mechanicalReduction>
    </actuator>
    <joint name="link2_to_link3_Zaxis">
      <hardwareInterface>hardware_interface/EffortJointInterface</hardwareInterface>
    </joint>
  </transmission>
  <transmission name="link3_to_link4_tran">
    <type>transmission_interface/SimpleTransmission</type>
    <actuator name="link3_to_link4_motor">
      <mechanicalReduction>1</mechanicalReduction>
    </actuator>
    <joint name="link3_to_link4_Xaxis">
      <hardwareInterface>hardware_interface/EffortJointInterface</hardwareInterface>
    </joint>
  </transmission>
  <transmission name="link4_to_link5_tran">
    <type>transmission_interface/SimpleTransmission</type>
    <actuator name="link4_to_link5_motor">
      <mechanicalReduction>1</mechanicalReduction>
    </actuator>
    <joint name="link4_to_link5_Zaxis">
      <hardwareInterface>hardware_interface/EffortJointInterface</hardwareInterface>
    </joint>
  </transmission>
  <transmission name="link5_to_link6_tran">
    <type>transmission_interface/SimpleTransmission</type>
    <actuator name="link5_to_link6_motor">
      <mechanicalReduction>1</mechanicalReduction>
    </actuator>
    <joint name="link5_to_link6_Xaxis">
      <hardwareInterface>hardware_interface/EffortJointInterface</hardwareInterface>
    </joint>
  </transmission>
  <transmission name="link6_to_link7_tran">
    <type>transmission_interface/SimpleTransmission</type>
    <actuator name="link6_to_link7_motor">
      <mechanicalReduction>1</mechanicalReduction>
    </actuator>
    <joint name="link6_to_link7_Zaxis">
      <hardwareInterface>hardware_interface/EffortJointInterface</hardwareInterface>
    </joint>
  </transmission>
  <transmission name="link7_to_link8_tran">
    <type>transmission_interface/SimpleTransmission</type>
    <actuator name="link7_to_link8_motor">
      <mechanicalReduction>1</mechanicalReduction>
    </actuator>
    <joint name="link7_to_link8_Xaxis">
      <hardwareInterface>hardware_interface/EffortJointInterface</hardwareInterface>
    </joint>
  </transmission>
  <!-- link to hold camera -->
  <link name="camera_link">
    <visual>
      <geometry>
        <box size="0.05 0.02 0.05"/>
      </geometry>
      <material name="white"/>
    </visual>
    <collision>
      <geometry>
        <box size="0.05 0.02 0.05"/>
      </geometry>
    </collision>
    <inertial>
      <origin rpy="0 0 0" xyz="0 0 0"/>
      <mass value="0.1"/>
      <!-- Calculate and set the inertia tensor values, formula source https://en.wikipedia.org/wiki/List_of_moments_of_inertia -->
      <inertia ixx="4.166666666666667e-05" ixy="0" ixz="0" iyy="2.4166666666666674e-05" iyz="0" izz="2.4166666666666674e-05"/>
    </inertial>
  </link>
  <joint name="link8_camera_joint" type="fixed">
    <parent link="link8"/>
    <child link="camera_link"/>
    <!-- the RPY is NOT 000 to make sure camera does not see inside ground but is over the surface -->
    <origin rpy="0 -0.18479956785822313 1.5707963267948966" xyz="0 0.42000000000000004 0"/>
  </joint>
  <!-- camera plugin for gazebo -->
  <gazebo reference="camera_link">
    <material>Gazebo/Red</material>
    <sensor name="camera_sensor" type="camera">
      <pose>0 0 0 0 0 0</pose>
      <visualize>true</visualize>
      <update_rate>10.0</update_rate>
      <plugin filename="libgazebo_ros_camera.so" name="camera_controller">
        <frame_name>camera_link</frame_name>
      </plugin>
    </sensor>
  </gazebo>
</robot>
